Workbook

Sheet Summary
A1: BOOST LED driver: bill of materials and cost
A2: Scenario A: 5 bare PCBs of each board, 2 complete sets assembled by JLCPCB. Updated 2026-10-02: schematic rev6 plus D28-D30, 6-layer control card with 0.5 oz inner copper, the savings approved on 2026-10-01, and the 6-layer power board (2026-10-02, stackup JLC061611-7628D). JLC prices and stock read 2026-10-01.
A4: Item | B4: Cost (USD) | C4: Notes
A5: Power board: PCBs + JLC assembly | B5: =Fees!B8 | C5: JLC order 1
A6: Control card: PCBs + JLC assembly | B6: =Fees!C8 | C6: JLC order 2
A7: Bought elsewhere: J10/J11, PTC, hardware, McMaster thermal pad | B7: ='Bought elsewhere'!E15 | C7: Mouser, LCSC, McMaster-Carr, Digi-Key, Newark/Farnell
A8: Total (shipping and tax not included) | B8: =SUM(B5:B7) | C8: COST_SUMMARY.md gives $599.01
A10: Stock (2026-10-01): every JLC line is in stock for 2 sets. Re-check on the day you order.
A11: Not included: M1-M10, L1, the buck module and J9 wires (you own them); case, cabling, Arduino, LEDs; shipping and tax.
A12: Edit a unit price or a quantity on the board sheets and every total updates.

Sheet Power board
A1: # | B1: Designators | C1: Qty / board | D1: Qty to order (2 boards + attrition) | E1: Description | F1: Manufacturer | G1: Part number (MPN) | H1: LCSC # | I1: Basic / Extended | J1: Unit price (USD, qty 1) | K1: Line cost (USD) | L1: JLC stock 2026-10-01 | M1: Footprint | N1: Side | O1: Fitted by | P1: JLC page | Q1: LCSC page | R1: Datasheet | S1: Value (schematic) | T1: Specs (JLC listing) | U1: Notes
A2: 1 | B2: C1 C4 C73 | C2: 3 | D2: =C2*2+0 | E2: ceramic capacitor 4.7uF 100 V X7R (1210) | F2: PSA(Prosperity Dielectrics) | G2: FS32X475K101EGG | H2: C381466 | I2: Extended | J2: 0.2328 | K2: =D2*J2 | L2: 172923 | M2: 1210 | N2: top | O2: JLC | P2: =HYPERLINK("https://jlcpcb.com/partdetail/354087-FS32X475K101EGG/C381466","JLC") | Q2: =HYPERLINK("https://www.lcsc.com/product-detail/multilayer-ceramic-capacitors-mlcc-smd-smt_psa-prosperity-dielectrics-fs32x475k101egg_C381466.html","LCSC") | R2: =HYPERLINK("https://wmsc.lcsc.com/wmsc/upload/file/pdf/v2/lcsc/2304140030_PSA-Prosperity-Dielectrics-FS32X475K101EGG_C381466.pdf","PDF") | S2: 4.7uF | T2: 100V 4.7uF X7R ±10% 1210 Multilayer Ceramic Capacitors MLCC - SMD/SMT ROHS | U2: on Vout (23-33 V running; TVS stand-off 54 V, clamp 87 V): 100 V rated; commutation-loop ceramic per rail; 50 V part C170099 is cheaper but keeps less capacitance at 33 V Alternates: C170099 (50 V)
A3: 2 | B3: C3 C72 C76 | C3: 3 | D3: =C3*2+20 | E3: ceramic capacitor 100nF 100 V X7R (0805) | F3: Samsung Electro-Mechanics | G3: CL21B104KCFNNNE | H3: C28233 | I3: Basic | J3: 0.0357 | K3: =D3*J3 | L3: 1258622 | M3: 0805 | N3: top | O3: JLC | P3: =HYPERLINK("https://jlcpcb.com/partdetail/28983-CL21B104KCFNNNE/C28233","JLC") | Q3: =HYPERLINK("https://www.lcsc.com/product-detail/multilayer-ceramic-capacitors-mlcc-smd-smt_samsung-electro-mechanics-cl21b104kcfnnne_C28233.html","LCSC") | R3: =HYPERLINK("https://www.lcsc.com/datasheet/lcsc_datasheet_2304140030_Samsung-Electro-Mechanics-CL21B104KCFNNNE_C28233.pdf","PDF") | S3: 100nF | T3: 100V 100nF X7R ±10% 0805 Multilayer Ceramic Capacitors MLCC - SMD/SMT ROHS | U3: on Vout (23-33 V running; TVS stand-off 54 V, clamp 87 V): 100 V rated
A4: 3 | B4: C6 C21 C25 C31 C62 C89 | C4: 6 | D4: =C4*2+20 | E4: ceramic capacitor 1uF 50 V X7R (0805) | F4: Samsung Electro-Mechanics | G4: CL21B105KBFNNNE | H4: C28323 | I4: Basic | J4: 0.0399 | K4: =D4*J4 | L4: 2288251 | M4: 0805 | N4: bottom/top | O4: JLC | P4: =HYPERLINK("https://jlcpcb.com/partdetail/29074-CL21B105KBFNNNE/C28323","JLC") | Q4: =HYPERLINK("https://www.lcsc.com/product-detail/multilayer-ceramic-capacitors-mlcc-smd-smt_samsung-electro-mechanics-cl21b105kbfnnne_C28323.html","LCSC") | R4: =HYPERLINK("https://www.lcsc.com/datasheet/lcsc_datasheet_2304140030_Samsung-Electro-Mechanics-CL21B105KBFNNNE_C28323.pdf","PDF") | S4: 1uF | T4: 1uF 50V X7R ±10% 0805 Multilayer Ceramic Capacitors MLCC - SMD/SMT ROHS | U4: value and package from the schematic; X7R, voltage rating at least 2x the net (rails 5/12 V, Vin 14-17 V)
A5: 4 | B5: C7 C55 | C5: 2 | D5: =C5*2+0 | E5: ceramic capacitor 22uF 25 V X7R (1210) | F5: Murata Electronics | G5: GRM32ER71E226KE15L | H5: C21397 | I5: Extended | J5: 0.4585 | K5: =D5*J5 | L5: 75388 | M5: 1210 | N5: top | O5: JLC | P5: =HYPERLINK("https://jlcpcb.com/partdetail/MurataElectronics-GRM32ER71E226KE15L/C21397","JLC") | Q5: =HYPERLINK("https://www.lcsc.com/product-detail/multilayer-ceramic-capacitors-mlcc-smd-smt_murata-electronics-grm32er71e226ke15l_C21397.html","LCSC") | R5: =HYPERLINK("https://www.lcsc.com/datasheet/lcsc_datasheet_2308111542_Murata-Electronics-GRM32ER71E226KE15L_C21397.pdf","PDF") | S5: 22uF | T5: 22uF 25V X7R ±10% 1210 Multilayer Ceramic Capacitors MLCC - SMD/SMT ROHS | U5: part chosen earlier (HANDOFF_SUMMARY / replace_notes / ANSWERS)
A6: 5 | B6: C16 C18 C60 | C6: 3 | D6: =C6*2+20 | E6: ceramic capacitor 2.2uF 50 V X7R (1206) | F6: Samsung Electro-Mechanics | G6: CL31B225KBHNNNE | H6: C50254 | I6: Basic | J6: 0.0857 | K6: =D6*J6 | L6: 389063 | M6: 1206 | N6: bottom | O6: JLC | P6: =HYPERLINK("https://jlcpcb.com/partdetail/51263-CL31B225KBHNNNE/C50254","JLC") | Q6: =HYPERLINK("https://www.lcsc.com/product-detail/multilayer-ceramic-capacitors-mlcc-smd-smt_samsung-electro-mechanics-cl31b225kbhnnne_C50254.html","LCSC") | R6: =HYPERLINK("https://www.lcsc.com/datasheet/lcsc_datasheet_2304140030_Samsung-Electro-Mechanics-CL31B225KBHNNNE_C50254.pdf","PDF") | S6: 2.2uF | T6: 2.2uF 50V X7R ±10% 1206 Multilayer Ceramic Capacitors MLCC - SMD/SMT ROHS | U6: value and package from the schematic; X7R, voltage rating at least 2x the net (rails 5/12 V, Vin 14-17 V); bootstrap caps, 12 V across
A7: 6 | B7: C20 C33 C34 C35 C48 C50 C51 C61 C82 C83 C84 C90 | C7: 12 | D7: =C7*2+20 | E7: ceramic capacitor 100nF 50 V X7R (0603) | F7: YAGEO | G7: CC0603KRX7R9BB104 | H7: C14663 | I7: Basic | J7: 0.0123 | K7: =D7*J7 | L7: 54422762 | M7: 0603 | N7: bottom/top | O7: JLC | P7: =HYPERLINK("https://jlcpcb.com/partdetail/YAGEO-CC0603KRX7R9BB104/C14663","JLC") | Q7: =HYPERLINK("https://www.lcsc.com/product-detail/multilayer-ceramic-capacitors-mlcc-smd-smt_yageo-cc0603krx7r9bb104_C14663.html","LCSC") | R7: =HYPERLINK("https://www.lcsc.com/datasheet/lcsc_datasheet_2211101700_YAGEO-CC0603KRX7R9BB104_C14663.pdf","PDF") | S7: 100nF | T7: 100nF 50V X7R ±10% 0603 Multilayer Ceramic Capacitors MLCC - SMD/SMT ROHS | U7: value and package from the schematic; X7R, voltage rating at least 2x the net (rails 5/12 V, Vin 14-17 V); C82-C84 on Vin (<= 17 V), 50 V part
A8: 7 | B8: C30 | C8: 1 | D8: =C8*2+0 | E8: 47 uF 25 V tantalum capacitor (low ESR, case D) | F8: Vishay Intertech | G8: TR3D476K025C0250 | H8: C4979367 | I8: Extended | J8: 1.099 | K8: =D8*J8 | L8: 63 | M8: EIA-7343 (D) | N8: top | O8: JLC | P8: =HYPERLINK("https://jlcpcb.com/partdetail/VishayIntertech-TR3D476K025C0250/C4979367","JLC") | Q8: =HYPERLINK("https://www.lcsc.com/product-detail/tantalum-capacitors_vishay-intertech-tr3d476k025c0250_C4979367.html","LCSC") | R8: =HYPERLINK("https://wmsc.lcsc.com/wmsc/upload/file/pdf/v2/lcsc/2312131210_Vishay-Intertech-TR3D476K025C0250_C4979367.pdf","PDF") | S8: 47uF tantalum | T8: -55℃~+125℃ 250mΩ 25V 47uF ±10% CASE-D-7343-34(mm) Tantalum Capacitors ROHS | U8: part chosen earlier (HANDOFF_SUMMARY / replace_notes / ANSWERS); U16 (12 V regulator) output, ESR 250 mOhm
A9: 8 | B9: C39 C56 C79 C80 C81 | C9: 5 | D9: =C9*2+0 | E9: ceramic capacitor 10uF 50 V X7R (1210) | F9: Samsung Electro-Mechanics | G9: CL32B106KBJNNNE | H9: C138687 | I9: Extended | J9: 0.3252 | K9: =D9*J9 | L9: 32750 | M9: 1210 | N9: top | O9: JLC | P9: =HYPERLINK("https://jlcpcb.com/partdetail/150006-CL32B106KBJNNNE/C138687","JLC") | Q9: =HYPERLINK("https://lcsc.com/product-detail/Multilayer-Ceramic-Capacitors-MLCC-SMD-SMT_Samsung-Electro-Mechanics-CL32B106KBJNNNE_C138687.html","LCSC") | R9: =HYPERLINK("https://datasheet.lcsc.com/lcsc/1912112237_Samsung-Electro-Mechanics-CL32B106KBJNNNE_C138687.pdf","PDF") | S9: 10uF | T9: 10uF 50V X7R ±10% 1210 Multilayer Ceramic Capacitors MLCC - SMD/SMT ROHS | U9: value and package from the schematic; X7R, voltage rating at least 2x the net (rails 5/12 V, Vin 14-17 V); C79-C81 on Vin: 50 V X7R
A10: 9 | B10: C40 C69 C85 | C10: 3 | D10: =C10*2+0 | E10: 680 uF 25 V hybrid polymer electrolytic capacitor | F10: PANASONIC | G10: EEH-ZU1E681UP | H10: C29664285 | I10: Extended | J10: 2.5409 | K10: =D10*J10 | L10: 10 | M10: CP_Elec_10x12.5 | N10: top | O10: JLC | P10: =HYPERLINK("https://jlcpcb.com/partdetail/PANASONIC-EEHZU1E681UP/C29664285","JLC") | S10: 680uF EEH-ZU1E681UP | T10: -55℃~+135℃ 10mm 10mΩ@100kHz 12.5mm 25V 3700mA@100kHz 4000hrs@135℃ 680uF Polarized SMD ±20% SMD,D10x12.8mm Hybrid Aluminum Electrolytic Capacitors ROHS | U10: part chosen earlier (HANDOFF_SUMMARY / replace_notes / ANSWERS); STOCK 10: enough for 3 boards (3 each)
A11: 10 | B11: C41 C44 C45 | C11: 3 | D11: =C11*2+20 | E11: ceramic capacitor 1nF 50 V X7R (0603) | F11: Samsung Electro-Mechanics | G11: CL10B102KB8NNNC | H11: C1588 | I11: Basic | J11: 0.0089 | K11: =D11*J11 | L11: 7811866 | M11: 0603 | N11: top | O11: JLC | P11: =HYPERLINK("https://jlcpcb.com/partdetail/1940-CL10B102KB8NNNC/C1588","JLC") | Q11: =HYPERLINK("https://www.lcsc.com/product-detail/multilayer-ceramic-capacitors-mlcc-smd-smt_samsung-electro-mechanics-cl10b102kb8nnnc_C1588.html","LCSC") | R11: =HYPERLINK("https://www.lcsc.com/datasheet/lcsc_datasheet_2304140030_Samsung-Electro-Mechanics-CL10B102KB8NNNC_C1588.pdf","PDF") | S11: 1nF | T11: 1nF 50V X7R ±10% 0603 Multilayer Ceramic Capacitors MLCC - SMD/SMT ROHS | U11: value and package from the schematic; X7R, voltage rating at least 2x the net (rails 5/12 V, Vin 14-17 V); IREF wiper filter Alternates: C163508 (C0G)
A12: 11 | B12: C74 C86 C87 | C12: 3 | D12: =C12*2+0 | E12: 220 uF 50 V hybrid polymer electrolytic capacitor (Panasonic ZU) | F12: PANASONIC | G12: EEH-ZU1H221P | H12: C6843593 | I12: Extended | J12: 2.8352 | K12: =D12*J12 | L12: 14 | M12: CP_Elec_10x16.5 | N12: top | O12: JLC | P12: =HYPERLINK("https://jlcpcb.com/partdetail/PANASONIC-EEHZU1H221P/C6843593","JLC") | Q12: =HYPERLINK("https://www.lcsc.com/product-detail/hybrid-aluminum-electrolytic-capacitors_panasonic-eeh-zu1h221p_C6843593.html","LCSC") | S12: 220uF EEH-ZU1H221P | T12: -55℃~+135℃ 10mm 10mΩ 16.8mm 220uF 4000hrs@135℃ 50V 780mA@100Hz Polarized SMD ±20% SMD,D10xL16.8mm Hybrid Aluminum Electrolytic Capacitors ROHS | U12: part chosen earlier (HANDOFF_SUMMARY / replace_notes / ANSWERS); the three most loaded output caps (BOOST_AUDIT section 6: up to 3.46 A); since 2026-10-01 the other six are EEH-ZS1H221P
A13: 12 | B13: C70 C71 C75 C77 C78 C88 | C13: 6 | D13: =C13*2+0 | E13: 220 uF 50 V hybrid polymer electrolytic capacitor (Panasonic ZS) | F13: PANASONIC | G13: EEHZS1H221P | H13: C385885 | I13: Extended | J13: 1.6338 | K13: =D13*J13 | L13: 1263 | M13: CP_Elec_10x16.5 | N13: top | O13: JLC | P13: =HYPERLINK("https://jlcpcb.com/partdetail/PANASONIC-EEHZS1H221P/C385885","JLC") | Q13: =HYPERLINK("https://www.lcsc.com/product-detail/hybrid-aluminum-electrolytic-capacitors_panasonic-eehzs1h221p_C385885.html","LCSC") | R13: =HYPERLINK("https://wmsc.lcsc.com/wmsc/upload/file/pdf/v2/lcsc/1912111437_PANASONIC-EEHZS1H221P_C385885.pdf","PDF") | S13: 220uF EEH-ZS1H221P | T13: -55℃~+135℃ 10mm 13mΩ 16.5mm 220uF 4000hrs@135℃ 50V 555mA@100Hz Polarized SMD ±20% SMD,D10xL16.5mm Hybrid Aluminum Electrolytic Capacitors ROHS | U13: approved 2026-10-01: same Panasonic hybrid family, size and footprint; 13 mOhm, 3.7 A (ZU: 10 mOhm, 5.2 A). These positions carry 1.90-2.37 A, 51-64 % of the ZS rating; cheaper, and the ZU had too little stock Alternates: C6843593 EEH-ZU1H221P
A14: 13 | B14: D2 D8 D11 D13 D14 D22 | C14: 6 | D14: =C14*2+20 | E14: Schottky diode 40 V 1 A | F14: Jiangsu Changjing Electronics Technology Co., Ltd. | G14: B5819W SL | H14: C8598 | I14: Basic | J14: 0.028 | K14: =D14*J14 | L14: 512334 | M14: SOD-123 | N14: bottom | O14: JLC | P14: =HYPERLINK("https://jlcpcb.com/partdetail/9093-B5819WSL/C8598","JLC") | Q14: =HYPERLINK("https://www.lcsc.com/product-detail/schottky-diodes_jiangsu-changjing-electronics-technology-co-ltd-b5819w-sl_C8598.html","LCSC") | R14: =HYPERLINK("https://www.lcsc.com/datasheet/lcsc_datasheet_2304140030_Jiangsu-Changjing-Electronics-Technology-Co---Ltd--B5819W-SL_C8598.pdf","PDF") | S14: B5819W (gate turn-off) | T14: 1A 40V 600mV@1A 9A Independent SOD-123 Schottky Diodes ROHS | U14: your choice of 2026-09-24; no diode type in the schematic (LTspice default diode). Anode on the FET gate, cathode to the driver side of the gate resistor: the turn-off path. Proposal B5819W (40 V 1 A Schottky, Basic) Alternates: C81598 1N4148W
A15: 14 | B15: D9 D10 D21 | C15: 3 | D15: =C15*2+20 | E15: switching diode 200 V 0.2 A | F15: Jiangsu Changjing Electronics Technology Co., Ltd. | G15: BAV21W | H15: C21565 | I15: Extended | J15: 0.0191 | K15: =D15*J15 | L15: 87375 | M15: SOD-123 | N15: bottom | O15: JLC | P15: =HYPERLINK("https://jlcpcb.com/partdetail/22286-BAV21W/C21565","JLC") | Q15: =HYPERLINK("https://www.lcsc.com/product-detail/switching-diodes_jiangsu-changjing-electronics-technology-co-ltd-bav21w_C21565.html","LCSC") | R15: =HYPERLINK("https://www.lcsc.com/datasheet/lcsc_datasheet_1811011112_Jiangsu-Changjing-Electronics-Technology-Co---Ltd--BAV21W_C21565.pdf","PDF") | S15: BAV21W (bootstrap) | T15: 1.25V@200mA 1.7A 100nA@200V 200V 200mA 500mW 50ns Independent SOD-123 Switching Diodes ROHS | U15: your choice of 2026-09-24; no diode type in the schematic. 12 V to the high-side VDDA: blocks the rail FET source voltage (up to Vout, 54-87 V under a clamp event). Proposal BAV21W (200 V, trr 50 ns) Alternates: C81598 1N4148W (75 V: too low)
A16: 15 | B16: D28 D29 D30 | C16: 3 | D16: =C16*2+20 | E16: rectifier diode 1000 V 2 A | F16: Shandong Jingdao Microelectronics | G16: S2MW | H16: C128729 | I16: Extended | J16: 0.0183 | K16: =D16*J16 | L16: 14395 | M16: SOD-123F | N16: bottom | O16: JLC | P16: =HYPERLINK("https://jlcpcb.com/partdetail/140015-S2MW/C128729","JLC") | Q16: =HYPERLINK("https://www.lcsc.com/product-detail/diodes-general-purpose_shandong-jingdao-microelectronics-s2mw_C128729.html","LCSC") | R16: =HYPERLINK("https://www.lcsc.com/datasheet/lcsc_datasheet_1810121033_Shandong-Jingdao-Microelectronics-S2MW_C128729.pdf","PDF") | S16: S2MW (pre-charge) | T16: -55℃~+150℃ 1.1V@2A 1kV 2A 50A 5uA@1000V Independent SOD-123F Diodes - General Purpose ROHS | U16: pre-charge diodes Vin -> Vout_1/2/3 (chosen 2026-09-29): 1000 V 2 A, IFSM 50 A; surge headroom 2.5x at an ideal battery (precharge_surge_2026-09-30), kept 2026-09-30 Alternates: C2900725 Foshan Blue Rocket S2MW
A17: 16 | B17: D19 | C17: 1 | D17: =C17*2+0 | E17: TVS diode 54 V stand-off, 5 kW | F17: hongjiacheng | G17: 5.0SMDJ54A | H17: C42394451 | I17: Extended | J17: 0.3951 | K17: =D17*J17 | L17: 9825 | M17: D_SMC | N17: bottom | O17: JLC | P17: =HYPERLINK("https://jlcpcb.com/partdetail/hongjiacheng-50SMDJ54A/C42394451","JLC") | S17: TVS 5.0SMDJ54A | T17: DO-214AB(SMC) ESD and Surge Protection (TVS/ESD) ROHS | U17: part chosen earlier (HANDOFF_SUMMARY / replace_notes / ANSWERS); Littelfuse has 1 in stock; R+O alternate (as decided 2026-09-15). Its listing gives the ratings but links no datasheet Alternates: C20415356 Littelfuse (stock 1); C5279851 SETsafe (published specs)
A18: 17 | B18: J10 | C18: 1 | D18: =C18*2 | E18: 2x15 socket strip, 2.54 mm, elevated (Samtec) | F18: Samtec | G18: ESQ-115-44-G-D | J18: 9.13 | K18: =D18*J18 | M18: PinSocket 2x15 | N18: top | O18: you (hand) | P18: =HYPERLINK("https://www.samtec.com/products/esq-115-44-g-d","Maker") | S18: ESQ-115-44-G-D | U18: Mouser price as listed on samtec.com (2026-09-25); bought by you, fitted by you. the device named in the schematic or the notes; not stocked at LCSC (only the -LL variant is listed, 0 in stock, $23.28); buy from Samtec / Digi-Key / Mouser Alternates: C5689183 ESQ-115-44-G-D-LL (stock 0)
A19: 18 | B19: L1 | C19: 1 | D19: =C19*2 | E19: 6.8 uH power inductor, 32 x 22.5 mm | F19: Codaca | G19: CSCF3218-6R8MC | M19: 32 x 22.5 mm SMD | N19: top | O19: you (hand) | S19: CSCF3218-6R8MC | U19: you own it; not priced. the device named in the schematic or the notes; the user owns it Alternates: C5629897 (stock 0)
A20: 19 | B20: M1 M2 M3 M4 M5 M6 M7 M8 M9 M10 | C20: 10 | D20: =C20*2 | E20: 100 V N-channel MOSFET (TO-220) | F20: HUAYI (HYG) | G20: HYG180N10LS1P | M20: TO-220 | N20: bottom | O20: you (hand) | S20: HYG180N10 | U20: you own ten; not priced. the device named in the schematic or the notes; the user owns ten Alternates: C2841917 HYG180N10LS1P
A21: 20 | B21: R1 | C21: 1 | D21: =C21*2+0 | E21: current-sense resistor 1 mOhm 4 W, 4-terminal | F21: BOURNS | G21: CSS4J-4026R-1L00F | H21: C2076400 | I21: Extended | J21: 1.7086 | K21: =D21*J21 | L21: 385 | M21: 4026 4-terminal | N21: top | O21: JLC | P21: =HYPERLINK("https://jlcpcb.com/partdetail/BOURNS-CSS4J_4026R1L00F/C2076400","JLC") | Q21: =HYPERLINK("https://www.lcsc.com/product-detail/current-sense-resistors-shunt-resistors_bourns-css4j-4026r-1l00f_C2076400.html","LCSC") | R21: =HYPERLINK("https://wmsc.lcsc.com/wmsc/upload/file/pdf/v2/lcsc/2304140030_BOURNS-CSS4J-4026R-1L00F_C2076400.pdf","PDF") | S21: 1m CSS4J-4026R-1L00F | T21: 1mΩ 4W Current Sense Resistor ±1% ±75ppm/℃ 4026 Current Sense Resistors / Shunt Resistors ROHS | U21: your choice of 2026-09-24; rev6: 1 mOhm with U25 = INA241A4 (100 V/V): Current stays 0.1 V/A. Same Bourns land pattern (series drawing), H 2.70 max against 2.93 Alternates: C2076167 CSS4J-4026K-2L00F 2 mOhm (0 stock)
A22: 21 | B22: R7 R52 R53 | C22: 3 | D22: =C22*2+0 | E22: current-sense resistor 50 mOhm 1 W, metal strip | F22: Vishay Intertech | G22: WSL2512R0500FEA | H22: C413486 | I22: Extended | J22: 0.2348 | K22: =D22*J22 | L22: 41066 | M22: 2512 | N22: top | O22: JLC | P22: =HYPERLINK("https://jlcpcb.com/partdetail/VishayIntertech-WSL2512R0500FEA/C413486","JLC") | Q22: =HYPERLINK("https://www.lcsc.com/product-detail/chip-resistor-surface-mount_vishay-intertech-wsl2512r0500fea_C413486.html","LCSC") | R22: =HYPERLINK("https://wmsc.lcsc.com/wmsc/upload/file/pdf/v2/lcsc/1912111437_Vishay-Intertech-WSL2512R0500FEA_C413486.pdf","PDF") | S22: 50 mOhm WSL2512 | T22: -65℃~+170℃ 1W 50mΩ ±1% ±75ppm/℃ 2512 Chip Resistor - Surface Mount ROHS | U22: your choice of 2026-09-24; LED current sinks: 2.63 A, 0.35 W each. The value sets the LED current, so the TCR matters: WSL2512 metal strip +/-75 ppm/C ($0.23) against thick film +/-800 ppm/C ($0.04) Alternates: C127698 thick film +/-800 ppm/C
A23: 22 | B23: R13 R23 R47 | C23: 3 | D23: =C23*2+20 | E23: resistor 220 ohm 1 % (0603) | F23: UNI-ROYAL(Uniroyal Elec) | G23: 0603WAF2200T5E | H23: C22962 | I23: Basic | J23: 0.0035 | K23: =D23*J23 | L23: 1903983 | M23: 0603 | N23: bottom/top | O23: JLC | P23: =HYPERLINK("https://jlcpcb.com/partdetail/23689-0603WAF2200T5E/C22962","JLC") | Q23: =HYPERLINK("https://www.lcsc.com/product-detail/chip-resistor-surface-mount_uni-royal-uniroyal-elec-0603waf2200t5e_C22962.html","LCSC") | R23: =HYPERLINK("https://www.lcsc.com/datasheet/lcsc_datasheet_2206010130_UNI-ROYAL-Uniroyal-Elec-0603WAF2200T5E_C22962.pdf","PDF") | S23: 220 | T23: -55℃~+155℃ 100mW 220Ω 75V Thick Film Resistor ±1% ±100ppm/℃ 0603 Chip Resistor - Surface Mount ROHS | U23: value and package from the schematic; 1% thick film, JLC Basic where one exists
A24: 23 | B24: R15 | C24: 1 | D24: =C24*2+20 | E24: resistor 10 ohm 1 % (0805) | F24: UNI-ROYAL(Uniroyal Elec) | G24: 0805W8F100JT5E | H24: C17415 | I24: Basic | J24: 0.004 | K24: =D24*J24 | L24: 6880485 | M24: 0805 | N24: bottom | O24: JLC | P24: =HYPERLINK("https://jlcpcb.com/partdetail/18103-0805W8F100JT5E/C17415","JLC") | Q24: =HYPERLINK("https://www.lcsc.com/product-detail/chip-resistor-surface-mount_uni-royal-uniroyal-elec-0805w8f100jt5e_C17415.html","LCSC") | R24: =HYPERLINK("https://www.lcsc.com/datasheet/lcsc_datasheet_2206010216_UNI-ROYAL-Uniroyal-Elec-0805W8F100JT5E_C17415.pdf","PDF") | S24: 10 | T24: -55℃~+155℃ 10Ω 125mW 150V Thick Film Resistor ±1% ±200ppm/℃ 0805 Chip Resistor - Surface Mount ROHS | U24: value and package from the schematic; 1% thick film, JLC Basic where one exists
A25: 24 | B25: R21 R48 R60 R72 | C25: 4 | D25: =C25*2+20 | E25: resistor 5.1 ohm 1 % (0805) | F25: UNI-ROYAL(Uniroyal Elec) | G25: 0805W8F510KT5E | H25: C17724 | I25: Basic | J25: 0.0041 | K25: =D25*J25 | L25: 418343 | M25: 0805 | N25: bottom | O25: JLC | P25: =HYPERLINK("https://jlcpcb.com/partdetail/18412-0805W8F510KT5E/C17724","JLC") | Q25: =HYPERLINK("https://www.lcsc.com/product-detail/chip-resistor-surface-mount_uni-royal-uniroyal-elec-0805w8f510kt5e_C17724.html","LCSC") | R25: =HYPERLINK("https://www.lcsc.com/datasheet/lcsc_datasheet_2206010200_UNI-ROYAL-Uniroyal-Elec-0805W8F510KT5E_C17724.pdf","PDF") | S25: 5.1 | T25: -55℃~+155℃ 125mW 150V 5.1Ω Thick Film Resistor ±1% ±200ppm/℃ 0805 Chip Resistor - Surface Mount ROHS | U25: your choice of 2026-09-24; rev6: 5 -> 5.1 Ohm (5.0 Ohm 0805 is not stocked), the value R59/R70 already use Alternates: C25273 4.99 Ohm
A26: 25 | B26: R22 R50 R56 | C26: 3 | D26: =C26*2+20 | E26: resistor 100 ohm 1 % (0603) | F26: UNI-ROYAL(Uniroyal Elec) | G26: 0603WAF1000T5E | H26: C22775 | I26: Basic | J26: 0.0031 | K26: =D26*J26 | L26: 11576722 | M26: 0603 | N26: top | O26: JLC | P26: =HYPERLINK("https://jlcpcb.com/partdetail/23502-0603WAF1000T5E/C22775","JLC") | Q26: =HYPERLINK("https://www.lcsc.com/product-detail/chip-resistor-surface-mount_uni-royal-uniroyal-elec-0603waf1000t5e_C22775.html","LCSC") | R26: =HYPERLINK("https://www.lcsc.com/datasheet/lcsc_datasheet_2411221126_UNI-ROYAL-Uniroyal-Elec-0603WAF1000T5E_C22775.pdf","PDF") | S26: 100 | T26: -55℃~+155℃ 100mW 100Ω 75V Thick Film Resistor ±1% ±100ppm/℃ 0603 Chip Resistor - Surface Mount ROHS | U26: value and package from the schematic; 1% thick film, JLC Basic where one exists
A27: 26 | B27: R49 R61 R62 R73 R74 R75 R76 R104 | C27: 8 | D27: =C27*2+20 | E27: resistor 10k ohm 1 % (0603) | F27: UNI-ROYAL(Uniroyal Elec) | G27: 0603WAF1002T5E | H27: C25804 | I27: Basic | J27: 0.0018 | K27: =D27*J27 | L27: 23109251 | M27: 0603 | N27: bottom/top | O27: JLC | P27: =HYPERLINK("https://jlcpcb.com/partdetail/26547-0603WAF1002T5E/C25804","JLC") | Q27: =HYPERLINK("https://www.lcsc.com/product-detail/chip-resistor-surface-mount_uni-royal-uniroyal-elec-0603waf1002t5e_C25804.html","LCSC") | R27: =HYPERLINK("https://www.lcsc.com/datasheet/lcsc_datasheet_2206010045_UNI-ROYAL-Uniroyal-Elec-0603WAF1002T5E_C25804.pdf","PDF") | S27: 10k | T27: -55℃~+155℃ 100mW 10kΩ 75V Thick Film Resistor ±1% ±100ppm/℃ 0603 Chip Resistor - Surface Mount ROHS | U27: value and package from the schematic; 1% thick film, JLC Basic where one exists
A28: 27 | B28: R59 R70 | C28: 2 | D28: =C28*2+0 | E28: resistor 5.1 ohm 1 % (0805) | F28: UNI-ROYAL(Uniroyal Elec) | G28: 0805W8F510KT5E | H28: C17724 | I28: Basic | J28: 0.0041 | K28: =D28*J28 | L28: 418343 | M28: 0805 | N28: bottom/top | O28: JLC | P28: =HYPERLINK("https://jlcpcb.com/partdetail/18412-0805W8F510KT5E/C17724","JLC") | Q28: =HYPERLINK("https://www.lcsc.com/product-detail/chip-resistor-surface-mount_uni-royal-uniroyal-elec-0805w8f510kt5e_C17724.html","LCSC") | R28: =HYPERLINK("https://www.lcsc.com/datasheet/lcsc_datasheet_2206010200_UNI-ROYAL-Uniroyal-Elec-0805W8F510KT5E_C17724.pdf","PDF") | S28: 5.1 | T28: -55℃~+155℃ 125mW 150V 5.1Ω Thick Film Resistor ±1% ±200ppm/℃ 0805 Chip Resistor - Surface Mount ROHS | U28: value and package from the schematic; 1% thick film, JLC Basic where one exists
A29: 28 | B29: U1 U17 | C29: 2 | D29: =C29*2+0 | E29: linear regulator 5 V 100 mA | F29: STMicroelectronics | G29: L78L05ACUTR | H29: C43116 | I29: Extended | J29: 0.102 | K29: =D29*J29 | L29: 21384 | M29: SOT-89 | N29: top | O29: JLC | P29: =HYPERLINK("https://jlcpcb.com/partdetail/STMicroelectronics-L78L05ACUTR/C43116","JLC") | Q29: =HYPERLINK("https://www.lcsc.com/product-detail/voltage-regulators-linear-low-drop-out-ldo-regulators_stmicroelectronics-l78l05acutr_C43116.html","LCSC") | R29: =HYPERLINK("https://www.lcsc.com/datasheet/lcsc_datasheet_1809200029_STMicroelectronics-L78L05ACUTR_C43116.pdf","PDF") | S29: L78L05 | T29: 0℃~+125℃@(Tj) 1 1.7V 100mA 20V 40uV 49dB@(120Hz) 5V 6mA Fixed Over Current Protection、Over Temperature Protection、Short Circuit Protection Positive SOT-89-3 Voltage Regulators - Linear, Low Drop Out (LDO) Regulators ROHS | U29: the device named in the schematic or the notes; ST L78L05ACUTR (pinout OUT-GND-IN as the symbol)
A30: 29 | B30: U6 U11 U12 | C30: 3 | D30: =C30*2+20 | E30: op-amp, rail-to-rail, 1 MHz | F30: Texas Instruments | G30: TLV9001IDBVR | H30: C398363 | I30: Extended | J30: 0.0979 | K30: =D30*J30 | L30: 48438 | M30: SOT-23-5 | N30: top | O30: JLC | P30: =HYPERLINK("https://jlcpcb.com/partdetail/TexasInstruments-TLV9001IDBVR/C398363","JLC") | Q30: =HYPERLINK("https://www.lcsc.com/product-detail/operational-amplifier_texas-instruments-tlv9001idbvr_C398363.html","LCSC") | R30: =HYPERLINK("https://www.lcsc.com/datasheet/lcsc_datasheet_2410010130_Texas-Instruments-TLV9001IDBVR_C398363.pdf","PDF") | S30: TLV9001 | T30: -2.75V~-900mV、900mV~2.75V -40℃~+125℃ 1 1.6mV 1.8V~5.5V 1MHz 2V/us 2pA 4.7nV/√Hz@1kHz 40mA 5pA 600nV/℃ 60uA 86dB Enable/shutdown function、EMI filtering/RF suppression Rail-to-Rail Input, Rail-to-Rail Output SOT-23-5 Operational Amplifier ROHS | U30: approved 2026-10-01: TI TLV9001IDBVR (the DBV part: pins 1 OUT, 2 V-, 3 IN+, 4 IN-, 5 V+, as the MCP6241; NOT the TLV9001U). 1 MHz, 2 V/us, 1.6 mV max offset. LTspice re-runs (30 ms, 25 % PWM, cold start) match the MCP6241 within 0.05 % Alternates: C49889 MCP6241T-E/OT (before 2026-10-01)
A31: 30 | B31: U8 U10 U15 U19 | C31: 4 | D31: =C31*2+0 | E31: isolated dual gate driver | F31: Texas Instruments | G31: UCC21520DWR | H31: C601651 | I31: Extended | J31: 0.8893 | K31: =D31*J31 | L31: 17156 | M31: SOIC-16W | N31: bottom | O31: JLC | P31: =HYPERLINK("https://jlcpcb.com/partdetail/TexasInstruments-UCC21520DWR/C601651","JLC") | Q31: =HYPERLINK("https://www.lcsc.com/product-detail/isolators-gate-drivers_texas-instruments-ucc21520dwr_C601651.html","LCSC") | R31: =HYPERLINK("https://www.lcsc.com/datasheet/lcsc_datasheet_2006102223_Texas-Instruments-UCC21520DWR_C601651.pdf","PDF") | S31: UCC21520DW | T31: -40℃~+150℃@(Tj) 0.8V~1.2V 1.2V~2V 125kV/us 2 3V~18V 45ns 45ns 4A 5700 6A 9.2V~25V MOSFET、IGBT SOIC-16-300mil Isolators - Gate Drivers ROHS | U31: the device named in the schematic or the notes
A32: 31 | B32: U16 | C32: 1 | D32: =C32*2+0 | E32: linear regulator 12 V 1 A (7812) | F32: onsemi | G32: MC7812BD2TR4G | H32: C231294 | I32: Extended | J32: 0.5316 | K32: =D32*J32 | L32: 2024 | M32: TO-263-3 | N32: top | O32: JLC | P32: =HYPERLINK("https://jlcpcb.com/partdetail/onsemi-MC7812BD2TR4G/C231294","JLC") | Q32: =HYPERLINK("https://www.lcsc.com/product-detail/voltage-regulators-linear-low-drop-out-ldo-regulators_onsemi-mc7812bd2tr4g_C231294.html","LCSC") | R32: =HYPERLINK("https://www.lcsc.com/datasheet/lcsc_datasheet_2210210200_onsemi-MC7812BD2TR4G_C231294.pdf","PDF") | S32: MC7812 | T32: -40℃~+125℃@(Tj) 1 12V 1A 27V 2V@(1.0A) 3.4mA 60dB@(120Hz) Fixed Over Temperature Protection、Short Circuit Protection Positive TO-263-2 Voltage Regulators - Linear, Low Drop Out (LDO) Regulators ROHS | U32: approved 2026-10-01: onsemi MC7812BD2TR4G. Its D2PAK (case 936) fits the TO-263-3 footprint: pins 1 IN and 3 OUT at 2.54 mm pitch, tab = pin 2 GND, the centre lead is cut (pad 2 stays empty, it is GND). 35 V in, -40 to +125 C. About 1.5 V dropout, so at the end of a 4S discharge the LEDs fade from about 12.7 V open-circuit (simulated: BOOST_split_boards/mc7812_lowbatt_2026-10-01) Alternates: C38744 MC7812CD2TR4G (0 to +125 C); C2877347 LM2940S-12/NOPB (before 2026-10-01)
A33: 32 | B33: U25 | C33: 1 | D33: =C33*2+0 | E33: current-sense amplifier, gain 100 | F33: Texas Instruments | G33: INA241A4IDR | H33: C22427873 | I33: Extended | J33: 3.5277 | K33: =D33*J33 | L33: 116 | M33: SOIC-8 | N33: top | O33: JLC | P33: =HYPERLINK("https://jlcpcb.com/partdetail/TexasInstruments-INA241A4IDR/C22427873","JLC") | S33: INA241A4 | T33: SOIC-8 Current Sense Amplifiers ROHS | U33: your choice of 2026-09-24; rev6: gain 100 V/V with the 1 mOhm R1; TI SBOSA30D: same SOIC-8 pinout for every gain, 1.1 MHz for all gains Alternates: C22427652 INA241A3IDR (rev5)
B35: Parts total (JLC lines, 2 boards + attrition) | K35: =SUMIFS(K2:K33,O2:O33,"JLC")
B36: Parts you buy or own (priced lines) | K36: =SUMIFS(K2:K33,O2:O33,"you (hand)")
B37: Unique JLC part numbers (feeder loading $1.53 each) | K37: 28

Sheet Control card
A1: # | B1: Designators | C1: Qty / board | D1: Qty to order (2 boards + attrition) | E1: Description | F1: Manufacturer | G1: Part number (MPN) | H1: LCSC # | I1: Basic / Extended | J1: Unit price (USD, qty 1) | K1: Line cost (USD) | L1: JLC stock 2026-10-01 | M1: Footprint | N1: Side | O1: Fitted by | P1: JLC page | Q1: LCSC page | R1: Datasheet | S1: Value (schematic) | T1: Specs (JLC listing) | U1: Notes
A2: 1 | B2: C8 C9 C17 C19 | C2: 4 | D2: =C2*2+20 | E2: ceramic capacitor 330pF 50 V C0G (0603) | F2: Samsung Electro-Mechanics | G2: CL10C331JB8NNNC | H2: C1664 | I2: Basic | J2: 0.0179 | K2: =D2*J2 | L2: 915282 | M2: 0603 | N2: bottom/top | O2: JLC | P2: =HYPERLINK("https://jlcpcb.com/partdetail/2016-CL10C331JB8NNNC/C1664","JLC") | Q2: =HYPERLINK("https://www.lcsc.com/product-detail/multilayer-ceramic-capacitors-mlcc-smd-smt_samsung-electro-mechanics-cl10c331jb8nnnc_C1664.html","LCSC") | R2: =HYPERLINK("https://www.lcsc.com/datasheet/lcsc_datasheet_2304140030_Samsung-Electro-Mechanics-CL10C331JB8NNNC_C1664.pdf","PDF") | S2: 330pF | T2: 330pF 50V C0G ±5% 0603 Multilayer Ceramic Capacitors MLCC - SMD/SMT ROHS | U2: timing / compensation / sample-and-hold: C0G
A3: 2 | B3: C10 C11 C13 | C3: 3 | D3: =C3*2+20 | E3: ceramic capacitor 4.7nF 50 V C0G (0603) | F3: Murata Electronics | G3: GRM1885C1H472JA01D | H3: C85980 | I3: Extended | J3: 0.0212 | K3: =D3*J3 | L3: 99447 | M3: 0603 | N3: bottom/top | O3: JLC | P3: =HYPERLINK("https://jlcpcb.com/partdetail/MurataElectronics-GRM1885C1H472JA01D/C85980","JLC") | Q3: =HYPERLINK("https://www.lcsc.com/product-detail/multilayer-ceramic-capacitors-mlcc-smd-smt_murata-electronics-grm1885c1h472ja01d_C85980.html","LCSC") | R3: =HYPERLINK("https://wmsc.lcsc.com/wmsc/upload/file/pdf/v2/lcsc/2304140030_Murata-Electronics-GRM1885C1H472JA01D_C85980.pdf","PDF") | S3: 4.7nF | T3: 4.7nF 50V C0G ±5% 0603 Multilayer Ceramic Capacitors MLCC - SMD/SMT ROHS | U3: timing / compensation / sample-and-hold: C0G; on Verr1-3 Alternates: C53987 X7R Basic
A4: 3 | B4: C12 C22 C23 C24 C26 C28 C29 C32 C36 C37 C38 C42 C43 C46 C52 C53 C54 C58 C59 C63 C65 C66 C68 C92 C94 C95 C96 C97 C98 C99 C104 | C4: 31 | D4: =C4*2+20 | E4: ceramic capacitor 100nF 50 V X7R (0603) | F4: YAGEO | G4: CC0603KRX7R9BB104 | H4: C14663 | I4: Basic | J4: 0.0123 | K4: =D4*J4 | L4: 54422762 | M4: 0603 | N4: bottom/top | O4: JLC | P4: =HYPERLINK("https://jlcpcb.com/partdetail/YAGEO-CC0603KRX7R9BB104/C14663","JLC") | Q4: =HYPERLINK("https://www.lcsc.com/product-detail/multilayer-ceramic-capacitors-mlcc-smd-smt_yageo-cc0603krx7r9bb104_C14663.html","LCSC") | R4: =HYPERLINK("https://www.lcsc.com/datasheet/lcsc_datasheet_2211101700_YAGEO-CC0603KRX7R9BB104_C14663.pdf","PDF") | S4: 100nF | T4: 100nF 50V X7R ±10% 0603 Multilayer Ceramic Capacitors MLCC - SMD/SMT ROHS | U4: value and package from the schematic; X7R, voltage rating at least 2x the net (rails 5/12 V, Vin 14-17 V)
A5: 4 | B5: C14 | C5: 1 | D5: =C5*2+20 | E5: ceramic capacitor 220pF 50 V C0G (0603) | F5: Samsung Electro-Mechanics | G5: CL10C221JB8NNNC | H5: C27675 | I5: Extended | J5: 0.0095 | K5: =D5*J5 | L5: 32979 | M5: 0603 | N5: top | O5: JLC | P5: =HYPERLINK("https://jlcpcb.com/partdetail/28425-CL10C221JB8NNNC/C27675","JLC") | Q5: =HYPERLINK("https://www.lcsc.com/product-detail/multilayer-ceramic-capacitors-mlcc-smd-smt_samsung-electro-mechanics-cl10c221jb8nnnc_C27675.html","LCSC") | R5: =HYPERLINK("https://www.lcsc.com/datasheet/lcsc_datasheet_2304140030_Samsung-Electro-Mechanics-CL10C221JB8NNNC_C27675.pdf","PDF") | S5: 220pF | T5: 220pF 50V C0G ±5% 0603 Multilayer Ceramic Capacitors MLCC - SMD/SMT ROHS | U5: timing / compensation / sample-and-hold: C0G; Q1 emitter Alternates: C1603 X7R Basic
A6: 5 | B6: C15 | C6: 1 | D6: =C6*2+20 | E6: ceramic capacitor 100pF 50 V C0G (0603) | F6: Samsung Electro-Mechanics | G6: CL10C101JB8NNNC | H6: C14858 | I6: Basic | J6: 0.0086 | K6: =D6*J6 | L6: 3911823 | M6: 0603 | N6: top | O6: JLC | P6: =HYPERLINK("https://jlcpcb.com/partdetail/15530-CL10C101JB8NNNC/C14858","JLC") | Q6: =HYPERLINK("https://www.lcsc.com/product-detail/multilayer-ceramic-capacitors-mlcc-smd-smt_samsung-electro-mechanics-cl10c101jb8nnnc_C14858.html","LCSC") | R6: =HYPERLINK("https://www.lcsc.com/datasheet/lcsc_datasheet_2304140030_Samsung-Electro-Mechanics-CL10C101JB8NNNC_C14858.pdf","PDF") | S6: 100pF | T6: 100pF 50V C0G ±5% 0603 Multilayer Ceramic Capacitors MLCC - SMD/SMT ROHS | U6: timing / compensation / sample-and-hold: C0G
A7: 6 | B7: C47 C93 C103 | C7: 3 | D7: =C7*2+20 | E7: ceramic capacitor 10uF 25 V X5R (0603) | F7: Samsung Electro-Mechanics | G7: CL10A106MA8NRNC | H7: C96446 | I7: Basic | J7: 0.0752 | K7: =D7*J7 | L7: 3361748 | M7: 0603 | N7: bottom | O7: JLC | P7: =HYPERLINK("https://jlcpcb.com/partdetail/97651-CL10A106MA8NRNC/C96446","JLC") | Q7: =HYPERLINK("https://www.lcsc.com/product-detail/multilayer-ceramic-capacitors-mlcc-smd-smt_samsung-electro-mechanics-cl10a106ma8nrnc_C96446.html","LCSC") | R7: =HYPERLINK("https://www.lcsc.com/datasheet/lcsc_datasheet_2304140030_Samsung-Electro-Mechanics-CL10A106MA8NRNC_C96446.pdf","PDF") | S7: 10uF | T7: 10uF 25V X5R ±20% 0603 Multilayer Ceramic Capacitors MLCC - SMD/SMT ROHS | U7: value and package from the schematic; X7R, voltage rating at least 2x the net (rails 5/12 V, Vin 14-17 V); Vref_1-3 (5 V): 25 V X5R
A8: 7 | B8: C49 C64 C67 | C8: 3 | D8: =C8*2+0 | E8: ceramic capacitor 100nF 50 V C0G (1206) | F8: Murata Electronics | G8: GRM31C5C1H104JA01L | H8: C97946 | I8: Extended | J8: 0.1849 | K8: =D8*J8 | L8: 88688 | M8: 1206 | N8: bottom | O8: JLC | P8: =HYPERLINK("https://jlcpcb.com/partdetail/MurataElectronics-GRM31C5C1H104JA01L/C97946","JLC") | Q8: =HYPERLINK("https://www.lcsc.com/product-detail/multilayer-ceramic-capacitors-mlcc-smd-smt_murata-electronics-grm31c5c1h104ja01l_C97946.html","LCSC") | R8: =HYPERLINK("https://www.lcsc.com/datasheet/lcsc_datasheet_1810201313_Murata-Electronics-GRM31C5C1H104JA01L_C97946.pdf","PDF") | S8: 100nF | T8: 100nF 50V C0G ±5% 1206 Multilayer Ceramic Capacitors MLCC - SMD/SMT ROHS | U8: timing / compensation / sample-and-hold: C0G; sample-and-hold into the 4066 switches Alternates: C14663-class X7R
A9: 8 | B9: C57 C91 | C9: 2 | D9: =C9*2+20 | E9: ceramic capacitor 1uF 50 V X7R (0805) | F9: Samsung Electro-Mechanics | G9: CL21B105KBFNNNE | H9: C28323 | I9: Basic | J9: 0.0399 | K9: =D9*J9 | L9: 2288251 | M9: 0805 | N9: bottom/top | O9: JLC | P9: =HYPERLINK("https://jlcpcb.com/partdetail/29074-CL21B105KBFNNNE/C28323","JLC") | Q9: =HYPERLINK("https://www.lcsc.com/product-detail/multilayer-ceramic-capacitors-mlcc-smd-smt_samsung-electro-mechanics-cl21b105kbfnnne_C28323.html","LCSC") | R9: =HYPERLINK("https://www.lcsc.com/datasheet/lcsc_datasheet_2304140030_Samsung-Electro-Mechanics-CL21B105KBFNNNE_C28323.pdf","PDF") | S9: 1uF | T9: 1uF 50V X7R ±10% 0805 Multilayer Ceramic Capacitors MLCC - SMD/SMT ROHS | U9: value and package from the schematic; X7R, voltage rating at least 2x the net (rails 5/12 V, Vin 14-17 V)
A10: 9 | B10: C100 C101 C102 | C10: 3 | D10: =C10*2+20 | E10: ceramic capacitor 1nF 50 V X7R (0603) | F10: Samsung Electro-Mechanics | G10: CL10B102KB8NNNC | H10: C1588 | I10: Basic | J10: 0.0089 | K10: =D10*J10 | L10: 7811866 | M10: 0603 | N10: bottom/top | O10: JLC | P10: =HYPERLINK("https://jlcpcb.com/partdetail/1940-CL10B102KB8NNNC/C1588","JLC") | Q10: =HYPERLINK("https://www.lcsc.com/product-detail/multilayer-ceramic-capacitors-mlcc-smd-smt_samsung-electro-mechanics-cl10b102kb8nnnc_C1588.html","LCSC") | R10: =HYPERLINK("https://www.lcsc.com/datasheet/lcsc_datasheet_2304140030_Samsung-Electro-Mechanics-CL10B102KB8NNNC_C1588.pdf","PDF") | S10: 1nF | T10: 1nF 50V X7R ±10% 0603 Multilayer Ceramic Capacitors MLCC - SMD/SMT ROHS | U10: value and package from the schematic; X7R, voltage rating at least 2x the net (rails 5/12 V, Vin 14-17 V); pot B-terminal filter
A11: 10 | B11: D1 D3 D4 D5 D6 D7 D15 D20 D24 D27 | C11: 10 | D11: =C11*2+20 | E11: small-signal diode 75 V | F11: ST(Semtech) | G11: 1N4148W | H11: C81598 | I11: Basic | J11: 0.0123 | K11: =D11*J11 | L11: 5212124 | M11: SOD-123 | N11: bottom/top | O11: JLC | P11: =HYPERLINK("https://jlcpcb.com/partdetail/ST_Semtech-1N4148W/C81598","JLC") | Q11: =HYPERLINK("https://www.lcsc.com/product-detail/switching-diodes_st-semtech-1n4148w_C81598.html","LCSC") | R11: =HYPERLINK("https://www.lcsc.com/datasheet/lcsc_datasheet_1811061725_ST-Semtech-1N4148W_C81598.pdf","PDF") | S11: 1N4148W (logic) | T11: 150mA 1A 1V@50mA 1uA@75V 400mW 4ns 75V Independent SOD-123 Switching Diodes ROHS | U11: your choice of 2026-09-24; no diode type in the schematic (LTspice default silicon diode). Proposal 1N4148W (Basic), the closest real part to what was simulated
A12: 11 | B12: D23 D25 D26 | C12: 3 | D12: =C12*2+20 | E12: Schottky diode 30 V 0.2 A | F12: Jiangsu Changjing Electronics Technology Co., Ltd. | G12: BAT54WS L9 | H12: C22629 | I12: Extended | J12: 0.0238 | K12: =D12*J12 | L12: 1078 | M12: SOD-323 | N12: bottom/top | O12: JLC | P12: =HYPERLINK("https://jlcpcb.com/partdetail/23356-BAT54WSL9/C22629","JLC") | Q12: =HYPERLINK("https://www.lcsc.com/product-detail/schottky-diodes_jiangsu-changjing-electronics-technology-co-ltd-bat54ws-l9_C22629.html","LCSC") | R12: =HYPERLINK("https://www.lcsc.com/datasheet/lcsc_datasheet_1809140116_Jiangsu-Changjing-Electronics-Technology-Co---Ltd--BAT54WS-L9_C22629.pdf","PDF") | S12: BAT54WS (Vref) | T12: 100mA 1V@100mA 2uA@25V 30V 600mA Independent SOD-323 Schottky Diodes ROHS | U12: your choice of 2026-09-24; no type in the schematic; the design notes show BAT54 on this path (Output -> .1Vref_n). Proposal BAT54WS Alternates: C124205 BAT54WS-7-F
A13: 12 | B13: J11 | C13: 1 | D13: =C13*2 | E13: 2x15 pin header, 2.54 mm (Samtec) | F13: Samtec | G13: TSW-115-07-G-D | J13: 3.18 | K13: =D13*J13 | M13: PinHeader 2x15 | N13: bottom | O13: you (hand) | P13: =HYPERLINK("https://www.samtec.com/products/tsw-115-07-g-d","Maker") | S13: TSW-115-07-G-D | U13: Mouser price as listed on samtec.com (2026-09-25); bought by you, fitted by you. the device named in the schematic or the notes; LCSC lists it with 0 in stock; buy from Samtec / Digi-Key / Mouser Alternates: C5994596 (stock 0)
A14: 13 | B14: Q1 | C14: 1 | D14: =C14*2+20 | E14: PNP transistor 40 V | F14: onsemi | G14: MMBT3906LT1G | H14: C53444 | I14: Extended | J14: 0.0189 | K14: =D14*J14 | L14: 1000823 | M14: SOT-23 | N14: bottom | O14: JLC | P14: =HYPERLINK("https://jlcpcb.com/partdetail/onsemi-MMBT3906LT1G/C53444","JLC") | Q14: =HYPERLINK("https://www.lcsc.com/product-detail/bipolar-bjt_onsemi-mmbt3906lt1g_C53444.html","LCSC") | R14: =HYPERLINK("https://www.lcsc.com/datasheet/lcsc_datasheet_1810301518_onsemi-MMBT3906LT1G_C53444.pdf","PDF") | S14: MMBT3906 | T14: -55℃~+150℃ 1 PNP 200mA 225mW 250MHz 250mV 40V 50nA 5V 60 PNP SOT-23 Bipolar (BJT) ROHS | U14: your choice of 2026-09-24; no transistor type in the schematic (LTspice generic PNP). Proposal MMBT3906 Alternates: C2143 JSCJ MMBT3906
A15: 14 | B15: R2 R6 R31 R33 R39 R41 R67 R77 R83 R85 R100 R101 R103 | C15: 13 | D15: =C15*2+20 | E15: resistor 10k ohm 1 % (0603) | F15: UNI-ROYAL(Uniroyal Elec) | G15: 0603WAF1002T5E | H15: C25804 | I15: Basic | J15: 0.0018 | K15: =D15*J15 | L15: 23109251 | M15: 0603 | N15: bottom/top | O15: JLC | P15: =HYPERLINK("https://jlcpcb.com/partdetail/26547-0603WAF1002T5E/C25804","JLC") | Q15: =HYPERLINK("https://www.lcsc.com/product-detail/chip-resistor-surface-mount_uni-royal-uniroyal-elec-0603waf1002t5e_C25804.html","LCSC") | R15: =HYPERLINK("https://www.lcsc.com/datasheet/lcsc_datasheet_2206010045_UNI-ROYAL-Uniroyal-Elec-0603WAF1002T5E_C25804.pdf","PDF") | S15: 10k | T15: -55℃~+155℃ 100mW 10kΩ 75V Thick Film Resistor ±1% ±100ppm/℃ 0603 Chip Resistor - Surface Mount ROHS | U15: value and package from the schematic; 1% thick film, JLC Basic where one exists
A16: 15 | B16: R3 R32 R40 | C16: 3 | D16: =C16*2+20 | E16: resistor 620k ohm 1 % (0603) | F16: UNI-ROYAL(Uniroyal Elec) | G16: 0603WAF6203T5E | H16: C23219 | I16: Extended | J16: 0.002 | K16: =D16*J16 | L16: 93537 | M16: 0603 | N16: bottom/top | O16: JLC | P16: =HYPERLINK("https://jlcpcb.com/partdetail/23946-0603WAF6203T5E/C23219","JLC") | Q16: =HYPERLINK("https://www.lcsc.com/product-detail/chip-resistor-surface-mount_uni-royal-uniroyal-elec-0603waf6203t5e_C23219.html","LCSC") | R16: =HYPERLINK("https://www.lcsc.com/datasheet/lcsc_datasheet_2206010116_UNI-ROYAL-Uniroyal-Elec-0603WAF6203T5E_C23219.pdf","PDF") | S16: 620k | T16: -55℃~+155℃ 100mW 620kΩ 75V Thick Film Resistor ±1% ±100ppm/℃ 0603 Chip Resistor - Surface Mount ROHS | U16: value and package from the schematic; 1% thick film, JLC Basic where one exists
A17: 16 | B17: R4 R54 R55 R58 R71 R99 R102 | C17: 7 | D17: =C17*2+20 | E17: resistor 1k ohm 1 % (0603) | F17: UNI-ROYAL(Uniroyal Elec) | G17: 0603WAF1001T5E | H17: C21190 | I17: Basic | J17: 0.0026 | K17: =D17*J17 | L17: 21672207 | M17: 0603 | N17: bottom/top | O17: JLC | P17: =HYPERLINK("https://jlcpcb.com/partdetail/21904-0603WAF1001T5E/C21190","JLC") | Q17: =HYPERLINK("https://www.lcsc.com/product-detail/chip-resistor-surface-mount_uni-royal-uniroyal-elec-0603waf1001t5e_C21190.html","LCSC") | R17: =HYPERLINK("https://www.lcsc.com/datasheet/lcsc_datasheet_2206010130_UNI-ROYAL-Uniroyal-Elec-0603WAF1001T5E_C21190.pdf","PDF") | S17: 1k | T17: -55℃~+155℃ 100mW 1kΩ 75V Thick Film Resistor ±1% ±100ppm/℃ 0603 Chip Resistor - Surface Mount ROHS | U17: value and package from the schematic; 1% thick film, JLC Basic where one exists
A18: 17 | B18: R8 R34 R42 R51 R63 R78 R80 | C18: 7 | D18: =C18*2+20 | E18: resistor 2k ohm 1 % (0603) | F18: UNI-ROYAL(Uniroyal Elec) | G18: 0603WAF2001T5E | H18: C22975 | I18: Basic | J18: 0.0024 | K18: =D18*J18 | L18: 13572776 | M18: 0603 | N18: bottom/top | O18: JLC | P18: =HYPERLINK("https://jlcpcb.com/partdetail/23702-0603WAF2001T5E/C22975","JLC") | Q18: =HYPERLINK("https://www.lcsc.com/product-detail/chip-resistor-surface-mount_uni-royal-uniroyal-elec-0603waf2001t5e_C22975.html","LCSC") | R18: =HYPERLINK("https://www.lcsc.com/datasheet/lcsc_datasheet_2206010116_UNI-ROYAL-Uniroyal-Elec-0603WAF2001T5E_C22975.pdf","PDF") | S18: 2k | T18: -55℃~+155℃ 100mW 2kΩ 75V Thick Film Resistor ±1% ±100ppm/℃ 0603 Chip Resistor - Surface Mount ROHS | U18: value and package from the schematic; 1% thick film, JLC Basic where one exists
A19: 18 | B19: R9 R35 R43 | C19: 3 | D19: =C19*2+20 | E19: resistor 18k ohm 1 % (0805) | F19: UNI-ROYAL(Uniroyal Elec) | G19: 0805W8F1802T5E | H19: C17506 | I19: Extended (preferred) | J19: 0.0043 | K19: =D19*J19 | L19: 194888 | M19: 0805 | N19: bottom/top | O19: JLC | P19: =HYPERLINK("https://jlcpcb.com/partdetail/18194-0805W8F1802T5E/C17506","JLC") | Q19: =HYPERLINK("https://www.lcsc.com/product-detail/chip-resistor-surface-mount_uni-royal-uniroyal-elec-0805w8f1802t5e_C17506.html","LCSC") | R19: =HYPERLINK("https://www.lcsc.com/datasheet/lcsc_datasheet_2206010216_UNI-ROYAL-Uniroyal-Elec-0805W8F1802T5E_C17506.pdf","PDF") | S19: 18k | T19: -55℃~+155℃ 125mW 150V 18kΩ Thick Film Resistor ±1% ±100ppm/℃ 0805 Chip Resistor - Surface Mount ROHS | U19: value and package from the schematic; 1% thick film, JLC Basic where one exists
A20: 19 | B20: R11 R17 | C20: 2 | D20: =C20*2+20 | E20: resistor 510k ohm 1 % (0603) | F20: UNI-ROYAL(Uniroyal Elec) | G20: 0603WAF5103T5E | H20: C23192 | I20: Basic | J20: 0.0024 | K20: =D20*J20 | L20: 894332 | M20: 0603 | N20: bottom | O20: JLC | P20: =HYPERLINK("https://jlcpcb.com/partdetail/23919-0603WAF5103T5E/C23192","JLC") | Q20: =HYPERLINK("https://www.lcsc.com/product-detail/chip-resistor-surface-mount_uni-royal-uniroyal-elec-0603waf5103t5e_C23192.html","LCSC") | R20: =HYPERLINK("https://www.lcsc.com/datasheet/lcsc_datasheet_2206010116_UNI-ROYAL-Uniroyal-Elec-0603WAF5103T5E_C23192.pdf","PDF") | S20: 510k | T20: -55℃~+155℃ 100mW 510kΩ 75V Thick Film Resistor ±1% ±100ppm/℃ 0603 Chip Resistor - Surface Mount ROHS | U20: value and package from the schematic; 1% thick film, JLC Basic where one exists
A21: 20 | B21: R16 R19 | C21: 2 | D21: =C21*2+20 | E21: resistor 5.1k ohm 1 % (0603) | F21: UNI-ROYAL(Uniroyal Elec) | G21: 0603WAF5101T5E | H21: C23186 | I21: Basic | J21: 0.0015 | K21: =D21*J21 | L21: 25280385 | M21: 0603 | N21: bottom/top | O21: JLC | P21: =HYPERLINK("https://jlcpcb.com/partdetail/23913-0603WAF5101T5E/C23186","JLC") | Q21: =HYPERLINK("https://www.lcsc.com/product-detail/chip-resistor-surface-mount_uni-royal-uniroyal-elec-0603waf5101t5e_C23186.html","LCSC") | R21: =HYPERLINK("https://www.lcsc.com/datasheet/lcsc_datasheet_2206010116_UNI-ROYAL-Uniroyal-Elec-0603WAF5101T5E_C23186.pdf","PDF") | S21: 5.1k | T21: -55℃~+155℃ 100mW 5.1kΩ 75V Thick Film Resistor ±1% ±100ppm/℃ 0603 Chip Resistor - Surface Mount ROHS | U21: value and package from the schematic; 1% thick film, JLC Basic where one exists
A22: 21 | B22: R18 R20 | C22: 2 | D22: =C22*2+20 | E22: resistor 200k ohm 1 % (0603) | F22: UNI-ROYAL(Uniroyal Elec) | G22: 0603WAF2003T5E | H22: C25811 | I22: Basic | J22: 0.0023 | K22: =D22*J22 | L22: 2473796 | M22: 0603 | N22: bottom | O22: JLC | P22: =HYPERLINK("https://jlcpcb.com/partdetail/26554-0603WAF2003T5E/C25811","JLC") | Q22: =HYPERLINK("https://www.lcsc.com/product-detail/chip-resistor-surface-mount_uni-royal-uniroyal-elec-0603waf2003t5e_C25811.html","LCSC") | R22: =HYPERLINK("https://www.lcsc.com/datasheet/lcsc_datasheet_2206010045_UNI-ROYAL-Uniroyal-Elec-0603WAF2003T5E_C25811.pdf","PDF") | S22: 200k | T22: -55℃~+155℃ 100mW 200kΩ 75V Thick Film Resistor ±1% ±100ppm/℃ 0603 Chip Resistor - Surface Mount ROHS | U22: value and package from the schematic; 1% thick film, JLC Basic where one exists
A23: 22 | B23: R25 R87 R94 | C23: 3 | D23: =C23*2+20 | E23: resistor 910k ohm 1 % (0805) | F23: UNI-ROYAL(Uniroyal Elec) | G23: 0805W8F9103T5E | H23: C17864 | I23: Extended | J23: 0.0034 | K23: =D23*J23 | L23: 15984 | M23: 0805 | N23: bottom/top | O23: JLC | P23: =HYPERLINK("https://jlcpcb.com/partdetail/18552-0805W8F9103T5E/C17864","JLC") | Q23: =HYPERLINK("https://www.lcsc.com/product-detail/chip-resistor-surface-mount_uni-royal-uniroyal-elec-0805w8f9103t5e_C17864.html","LCSC") | R23: =HYPERLINK("https://www.lcsc.com/datasheet/lcsc_datasheet_2206010200_UNI-ROYAL-Uniroyal-Elec-0805W8F9103T5E_C17864.pdf","PDF") | S23: 910k | T23: -55℃~+155℃ 125mW 150V 910kΩ Thick Film Resistor ±1% ±100ppm/℃ 0805 Chip Resistor - Surface Mount ROHS | U23: value and package from the schematic; 1% thick film, JLC Basic where one exists; Vout dividers: 150 V rated
A24: 23 | B24: R26 R64 R79 R81 | C24: 4 | D24: =C24*2+20 | E24: resistor 220 ohm 1 % (0603) | F24: UNI-ROYAL(Uniroyal Elec) | G24: 0603WAF2200T5E | H24: C22962 | I24: Basic | J24: 0.0035 | K24: =D24*J24 | L24: 1903983 | M24: 0603 | N24: bottom/top | O24: JLC | P24: =HYPERLINK("https://jlcpcb.com/partdetail/23689-0603WAF2200T5E/C22962","JLC") | Q24: =HYPERLINK("https://www.lcsc.com/product-detail/chip-resistor-surface-mount_uni-royal-uniroyal-elec-0603waf2200t5e_C22962.html","LCSC") | R24: =HYPERLINK("https://www.lcsc.com/datasheet/lcsc_datasheet_2206010130_UNI-ROYAL-Uniroyal-Elec-0603WAF2200T5E_C22962.pdf","PDF") | S24: 220 | T24: -55℃~+155℃ 100mW 220Ω 75V Thick Film Resistor ±1% ±100ppm/℃ 0603 Chip Resistor - Surface Mount ROHS | U24: value and package from the schematic; 1% thick film, JLC Basic where one exists
A25: 24 | B25: R27 R37 R45 R106 R107 | C25: 5 | D25: =C25*2+20 | E25: resistor 4.7k ohm 1 % (0603) | F25: UNI-ROYAL(Uniroyal Elec) | G25: 0603WAF4701T5E | H25: C23162 | I25: Basic | J25: 0.0028 | K25: =D25*J25 | L25: 22492816 | M25: 0603 | N25: bottom/top | O25: JLC | P25: =HYPERLINK("https://jlcpcb.com/partdetail/23889-0603WAF4701T5E/C23162","JLC") | Q25: =HYPERLINK("https://www.lcsc.com/product-detail/chip-resistor-surface-mount_uni-royal-uniroyal-elec-0603waf4701t5e_C23162.html","LCSC") | R25: =HYPERLINK("https://www.lcsc.com/datasheet/lcsc_datasheet_2206010116_UNI-ROYAL-Uniroyal-Elec-0603WAF4701T5E_C23162.pdf","PDF") | S25: 4.7k | T25: -55℃~+155℃ 100mW 4.7kΩ 75V Thick Film Resistor ±1% ±100ppm/℃ 0603 Chip Resistor - Surface Mount ROHS | U25: value and package from the schematic; 1% thick film, JLC Basic where one exists
A26: 25 | B26: R28 R36 R38 R44 R46 R88 R91 R95 R96 R105 | C26: 10 | D26: =C26*2+20 | E26: resistor 100k ohm 1 % (0603) | F26: UNI-ROYAL(Uniroyal Elec) | G26: 0603WAF1003T5E | H26: C25803 | I26: Basic | J26: 0.0031 | K26: =D26*J26 | L26: 22167984 | M26: 0603 | N26: bottom/top | O26: JLC | P26: =HYPERLINK("https://jlcpcb.com/partdetail/26546-0603WAF1003T5E/C25803","JLC") | Q26: =HYPERLINK("https://www.lcsc.com/product-detail/chip-resistor-surface-mount_uni-royal-uniroyal-elec-0603waf1003t5e_C25803.html","LCSC") | R26: =HYPERLINK("https://www.lcsc.com/datasheet/lcsc_datasheet_2206010045_UNI-ROYAL-Uniroyal-Elec-0603WAF1003T5E_C25803.pdf","PDF") | S26: 100k | T26: -55℃~+155℃ 100kΩ 100mW 75V Thick Film Resistor ±1% ±100ppm/℃ 0603 Chip Resistor - Surface Mount ROHS | U26: value and package from the schematic; 1% thick film, JLC Basic where one exists
A27: 26 | B27: R29 R30 R57 | C27: 3 | D27: =C27*2+20 | E27: resistor 22k ohm 1 % (0805) | F27: UNI-ROYAL(Uniroyal Elec) | G27: 0805W8F2202T5E | H27: C17560 | I27: Basic | J27: 0.0048 | K27: =D27*J27 | L27: 1746324 | M27: 0805 | N27: top | O27: JLC | P27: =HYPERLINK("https://jlcpcb.com/partdetail/18248-0805W8F2202T5E/C17560","JLC") | Q27: =HYPERLINK("https://www.lcsc.com/product-detail/chip-resistor-surface-mount_uni-royal-uniroyal-elec-0805w8f2202t5e_C17560.html","LCSC") | R27: =HYPERLINK("https://www.lcsc.com/datasheet/lcsc_datasheet_2206010200_UNI-ROYAL-Uniroyal-Elec-0805W8F2202T5E_C17560.pdf","PDF") | S27: 22k | T27: -55℃~+155℃ 125mW 150V 22kΩ Thick Film Resistor ±1% ±100ppm/℃ 0805 Chip Resistor - Surface Mount ROHS | U27: value and package from the schematic; 1% thick film, JLC Basic where one exists
A28: 27 | B28: R65 | C28: 1 | D28: =C28*2+20 | E28: resistor 22k ohm 1 % (0603) | F28: UNI-ROYAL(Uniroyal Elec) | G28: 0603WAF2202T5E | H28: C31850 | I28: Basic | J28: 0.0041 | K28: =D28*J28 | L28: 3706362 | M28: 0603 | N28: top | O28: JLC | P28: =HYPERLINK("https://jlcpcb.com/partdetail/32812-0603WAF2202T5E/C31850","JLC") | Q28: =HYPERLINK("https://www.lcsc.com/product-detail/chip-resistor-surface-mount_uni-royal-uniroyal-elec-0603waf2202t5e_C31850.html","LCSC") | R28: =HYPERLINK("https://www.lcsc.com/datasheet/lcsc_datasheet_2206010030_UNI-ROYAL-Uniroyal-Elec-0603WAF2202T5E_C31850.pdf","PDF") | S28: 22k | T28: -55℃~+155℃ 100mW 22kΩ 75V Thick Film Resistor ±1% ±100ppm/℃ 0603 Chip Resistor - Surface Mount ROHS | U28: value and package from the schematic; 1% thick film, JLC Basic where one exists
A29: 28 | B29: R66 R89 R92 R97 | C29: 4 | D29: =C29*2+20 | E29: resistor 3.3k ohm 1 % (0603) | F29: UNI-ROYAL(Uniroyal Elec) | G29: 0603WAF3301T5E | H29: C22978 | I29: Basic | J29: 0.0026 | K29: =D29*J29 | L29: 5696130 | M29: 0603 | N29: bottom/top | O29: JLC | P29: =HYPERLINK("https://jlcpcb.com/partdetail/23705-0603WAF3301T5E/C22978","JLC") | Q29: =HYPERLINK("https://www.lcsc.com/product-detail/chip-resistor-surface-mount_uni-royal-uniroyal-elec-0603waf3301t5e_C22978.html","LCSC") | R29: =HYPERLINK("https://www.lcsc.com/datasheet/lcsc_datasheet_2206010116_UNI-ROYAL-Uniroyal-Elec-0603WAF3301T5E_C22978.pdf","PDF") | S29: 3.3k | T29: -55℃~+155℃ 100mW 3.3kΩ 75V Thick Film Resistor ±1% ±100ppm/℃ 0603 Chip Resistor - Surface Mount ROHS | U29: value and package from the schematic; 1% thick film, JLC Basic where one exists
A30: 29 | B30: R68 | C30: 1 | D30: =C30*2+20 | E30: resistor 62k ohm 1 % (0603) | F30: UNI-ROYAL(Uniroyal Elec) | G30: 0603WAF6202T5E | H30: C23221 | I30: Extended (preferred) | J30: 0.0028 | K30: =D30*J30 | L30: 418136 | M30: 0603 | N30: top | O30: JLC | P30: =HYPERLINK("https://jlcpcb.com/partdetail/23948-0603WAF6202T5E/C23221","JLC") | Q30: =HYPERLINK("https://www.lcsc.com/product-detail/chip-resistor-surface-mount_uni-royal-uniroyal-elec-0603waf6202t5e_C23221.html","LCSC") | R30: =HYPERLINK("https://www.lcsc.com/datasheet/lcsc_datasheet_2206010116_UNI-ROYAL-Uniroyal-Elec-0603WAF6202T5E_C23221.pdf","PDF") | S30: 62k | T30: -55℃~+155℃ 100mW 62kΩ 75V Thick Film Resistor ±1% ±100ppm/℃ 0603 Chip Resistor - Surface Mount ROHS | U30: value and package from the schematic; 1% thick film, JLC Basic where one exists
A31: 30 | B31: R69 | C31: 1 | D31: =C31*2+20 | E31: resistor 20k ohm 1 % (0603) | F31: UNI-ROYAL(Uniroyal Elec) | G31: 0603WAF2002T5E | H31: C4184 | I31: Basic | J31: 0.0023 | K31: =D31*J31 | L31: 8044733 | M31: 0603 | N31: top | O31: JLC | P31: =HYPERLINK("https://jlcpcb.com/partdetail/4591-0603WAF2002T5E/C4184","JLC") | Q31: =HYPERLINK("https://www.lcsc.com/product-detail/chip-resistor-surface-mount_uni-royal-uniroyal-elec-0603waf2002t5e_C4184.html","LCSC") | R31: =HYPERLINK("https://www.lcsc.com/datasheet/lcsc_datasheet_2206010230_UNI-ROYAL-Uniroyal-Elec-0603WAF2002T5E_C4184.pdf","PDF") | S31: 20k | T31: -55℃~+155℃ 100mW 20kΩ 75V Thick Film Resistor ±1% ±100ppm/℃ 0603 Chip Resistor - Surface Mount ROHS | U31: value and package from the schematic; 1% thick film, JLC Basic where one exists
A32: 31 | B32: R82 | C32: 1 | D32: =C32*2+20 | E32: resistor 56k ohm 1 % (0603) | F32: UNI-ROYAL(Uniroyal Elec) | G32: 0603WAF5602T5E | H32: C23206 | I32: Basic | J32: 0.0027 | K32: =D32*J32 | L32: 1026495 | M32: 0603 | N32: top | O32: JLC | P32: =HYPERLINK("https://jlcpcb.com/partdetail/23933-0603WAF5602T5E/C23206","JLC") | Q32: =HYPERLINK("https://www.lcsc.com/product-detail/chip-resistor-surface-mount_uni-royal-uniroyal-elec-0603waf5602t5e_C23206.html","LCSC") | R32: =HYPERLINK("https://www.lcsc.com/datasheet/lcsc_datasheet_2206010116_UNI-ROYAL-Uniroyal-Elec-0603WAF5602T5E_C23206.pdf","PDF") | S32: 56k | T32: -55℃~+155℃ 100mW 56kΩ 75V Thick Film Resistor ±1% ±100ppm/℃ 0603 Chip Resistor - Surface Mount ROHS | U32: value and package from the schematic; 1% thick film, JLC Basic where one exists
A33: 32 | B33: R84 | C33: 1 | D33: =C33*2+20 | E33: resistor 120k ohm 1 % (0603) | F33: UNI-ROYAL(Uniroyal Elec) | G33: 0603WAF1203T5E | H33: C25808 | I33: Basic | J33: 0.0015 | K33: =D33*J33 | L33: 1007305 | M33: 0603 | N33: bottom | O33: JLC | P33: =HYPERLINK("https://jlcpcb.com/partdetail/26551-0603WAF1203T5E/C25808","JLC") | Q33: =HYPERLINK("https://www.lcsc.com/product-detail/chip-resistor-surface-mount_uni-royal-uniroyal-elec-0603waf1203t5e_C25808.html","LCSC") | R33: =HYPERLINK("https://www.lcsc.com/datasheet/lcsc_datasheet_2206010045_UNI-ROYAL-Uniroyal-Elec-0603WAF1203T5E_C25808.pdf","PDF") | S33: 120k | T33: -55℃~+155℃ 100mW 120kΩ 75V Thick Film Resistor ±1% ±100ppm/℃ 0603 Chip Resistor - Surface Mount ROHS | U33: value and package from the schematic; 1% thick film, JLC Basic where one exists
A34: 33 | B34: R86 | C34: 1 | D34: =C34*2+20 | E34: resistor 1M ohm 1 % (0805) | F34: UNI-ROYAL(Uniroyal Elec) | G34: 0805W8F1004T5E | H34: C17514 | I34: Basic | J34: 0.0043 | K34: =D34*J34 | L34: 2420510 | M34: 0805 | N34: top | O34: JLC | P34: =HYPERLINK("https://jlcpcb.com/partdetail/18202-0805W8F1004T5E/C17514","JLC") | Q34: =HYPERLINK("https://www.lcsc.com/product-detail/chip-resistor-surface-mount_uni-royal-uniroyal-elec-0805w8f1004t5e_C17514.html","LCSC") | R34: =HYPERLINK("https://www.lcsc.com/datasheet/lcsc_datasheet_2206010200_UNI-ROYAL-Uniroyal-Elec-0805W8F1004T5E_C17514.pdf","PDF") | S34: 1M | T34: -55℃~+155℃ 125mW 150V 1MΩ Thick Film Resistor ±1% ±100ppm/℃ 0805 Chip Resistor - Surface Mount ROHS | U34: value and package from the schematic; 1% thick film, JLC Basic where one exists
A35: 34 | B35: R90 R93 R98 | C35: 3 | D35: =C35*2+20 | E35: resistor 10M ohm 1 % (0603) | F35: UNI-ROYAL(Uniroyal Elec) | G35: 0603WAF1005T5E | H35: C7250 | I35: Basic | J35: 0.0037 | K35: =D35*J35 | L35: 297135 | M35: 0603 | N35: bottom/top | O35: JLC | P35: =HYPERLINK("https://jlcpcb.com/partdetail/7726-0603WAF1005T5E/C7250","JLC") | Q35: =HYPERLINK("https://www.lcsc.com/product-detail/chip-resistor-surface-mount_uni-royal-uniroyal-elec-0603waf1005t5e_C7250.html","LCSC") | R35: =HYPERLINK("https://www.lcsc.com/datasheet/lcsc_datasheet_2206010216_UNI-ROYAL-Uniroyal-Elec-0603WAF1005T5E_C7250.pdf","PDF") | S35: 10M | T35: -55℃~+155℃ 100mW 10MΩ 75V Thick Film Resistor ±1% ±100ppm/℃ 0603 Chip Resistor - Surface Mount ROHS | U35: value and package from the schematic; 1% thick film, JLC Basic where one exists
A36: 35 | B36: U2 U4 U5 U14 U21 | C36: 5 | D36: =C36*2+0 | E36: comparator, push-pull, 56 ns | F36: Microchip Tech | G36: MCP6561T-E/OT | H36: C117501 | I36: Extended | J36: 0.743 | K36: =D36*J36 | L36: 4005 | M36: SOT-23-5 | N36: bottom/top | O36: JLC | P36: =HYPERLINK("https://jlcpcb.com/partdetail/MicrochipTech-MCP6561T_EOT/C117501","JLC") | Q36: =HYPERLINK("https://www.lcsc.com/product-detail/comparators_microchip-tech-mcp6561t-e-ot_C117501.html","LCSC") | R36: =HYPERLINK("https://www.lcsc.com/datasheet/lcsc_datasheet_2304140030_Microchip-Tech-MCP6561T-E-OT_C117501.pdf","PDF") | S36: MCP6561 | T36: -40℃~+125℃ 1 1.8V~5.5V 100uA 1pA 1pA 2.5mV 20ns 2uV/℃ 3mV 56ns 6.5V 66dB ESD protection、Built-in hysteresis Push-pull Rail-to-rail input TTL、CMOS SOT-23-5 Comparators ROHS | U36: the device named in the schematic or the notes
A37: 36 | B37: U3 U7 U13 U22 U23 U24 | C37: 6 | D37: =C37*2+20 | E37: op-amp, rail-to-rail, 1 MHz | F37: Texas Instruments | G37: TLV9001IDBVR | H37: C398363 | I37: Extended | J37: 0.0979 | K37: =D37*J37 | L37: 48438 | M37: SOT-23-5 | N37: bottom/top | O37: JLC | P37: =HYPERLINK("https://jlcpcb.com/partdetail/TexasInstruments-TLV9001IDBVR/C398363","JLC") | Q37: =HYPERLINK("https://www.lcsc.com/product-detail/operational-amplifier_texas-instruments-tlv9001idbvr_C398363.html","LCSC") | R37: =HYPERLINK("https://www.lcsc.com/datasheet/lcsc_datasheet_2410010130_Texas-Instruments-TLV9001IDBVR_C398363.pdf","PDF") | S37: TLV9001 | T37: -2.75V~-900mV、900mV~2.75V -40℃~+125℃ 1 1.6mV 1.8V~5.5V 1MHz 2V/us 2pA 4.7nV/√Hz@1kHz 40mA 5pA 600nV/℃ 60uA 86dB Enable/shutdown function、EMI filtering/RF suppression Rail-to-Rail Input, Rail-to-Rail Output SOT-23-5 Operational Amplifier ROHS | U37: approved 2026-10-01: TI TLV9001IDBVR (the DBV part: pins 1 OUT, 2 V-, 3 IN+, 4 IN-, 5 V+, as the MCP6241; NOT the TLV9001U). 1 MHz, 2 V/us, 1.6 mV max offset. LTspice re-runs (30 ms, 25 % PWM, cold start) match the MCP6241 within 0.05 % Alternates: C49889 MCP6241T-E/OT (before 2026-10-01)
A38: 37 | B38: U18 | C38: 1 | D38: =C38*2+0 | E38: decade counter (CMOS 4017) | F38: Texas Instruments | G38: CD4017BM96 | H38: C11349 | I38: Extended | J38: 0.7267 | K38: =D38*J38 | L38: 18267 | M38: SOIC-16 | N38: top | O38: JLC | P38: =HYPERLINK("https://jlcpcb.com/partdetail/TexasInstruments-CD4017BM96/C11349","JLC") | Q38: =HYPERLINK("https://www.lcsc.com/product-detail/counters-dividers_texas-instruments-cd4017bm96_C11349.html","LCSC") | R38: =HYPERLINK("https://www.lcsc.com/datasheet/lcsc_datasheet_1809042113_Texas-Instruments-CD4017BM96_C11349.pdf","PDF") | S38: CD4017B | T38: -55℃~+125℃ 1 135ns 3V~18V 5.5MHz Asynchronous Divide-by-10 Rising Edge Up Counter SOIC-16 Counters, Dividers ROHS | U38: the device named in the schematic or the notes
